2024-02-08T17:07:47 {"cpu": 1.54541015625, "cpu_total": 4, "cpu_usage": 0.3863525390625, "memory": 8166.0, "memory_total": 9682.0, "memory_usage": 0.843420780830407, "pipeline_run_id": 1, "pipeline_schedule_id": 1, "pipeline_uuid": "green_taxi_etl", "hostname": "d3de16eb1433", "level": "INFO", "message": "Pipeline green_taxi_etl for run 1 in schedule 1 is alive.", "timestamp": 1707412067.20874, "uuid": "4295f0ed37d74f51a9d84c65247ccc43"}
2024-02-08T17:07:47 {"cpu": 1.54541015625, "cpu_total": 4, "cpu_usage": 0.3863525390625, "memory": 8268.0, "memory_total": 9682.0, "memory_usage": 0.8539557942573849, "pipeline_run_id": 1, "pipeline_schedule_id": 1, "pipeline_uuid": "green_taxi_etl", "hostname": "d3de16eb1433", "level": "INFO", "message": "Pipeline green_taxi_etl for run 1 in schedule 1 is alive.", "timestamp": 1707412067.632991, "uuid": "9ab6dd47be0b46d18f29336391584731"}
2024-02-08T17:07:47 {"block_run_id": 1, "block_uuid": "download_taxi_data", "pipeline_run_id": 1, "pipeline_schedule_id": 1, "pipeline_uuid": "green_taxi_etl", "hostname": "d3de16eb1433", "level": "INFO", "message": "Execute PipelineRun 1, BlockRun 1: pipeline green_taxi_etl block download_taxi_data", "timestamp": 1707412067.652705, "uuid": "619b1880fd09432a9ef2eb3076d085ae"}
2024-02-08T17:07:57 {"cpu": 1.57763671875, "cpu_total": 4, "cpu_usage": 0.3944091796875, "memory": 8576.0, "memory_total": 9682.0, "memory_usage": 0.8857674034290436, "pipeline_run_id": 1, "pipeline_schedule_id": 1, "pipeline_uuid": "green_taxi_etl", "hostname": "d3de16eb1433", "level": "INFO", "message": "Pipeline green_taxi_etl for run 1 in schedule 1 is alive.", "timestamp": 1707412077.103392, "uuid": "e2125f4478d2410abfba843c9edd6402"}
2024-02-08T17:07:58 {"block_run_id": 1, "block_uuid": "download_taxi_data", "pipeline_run_id": 1, "pipeline_schedule_id": 1, "pipeline_uuid": "green_taxi_etl", "hostname": "d3de16eb1433", "level": "INFO", "message": "BlockRun 1 (block_uuid: download_taxi_data) completes.", "timestamp": 1707412078.473656, "uuid": "ad261b2119b9447493307180745f9ccc"}
2024-02-08T17:08:06 {"cpu": 1.5986328125, "cpu_total": 4, "cpu_usage": 0.399658203125, "memory": 8439.0, "memory_total": 9682.0, "memory_usage": 0.8716174344143772, "pipeline_run_id": 1, "pipeline_schedule_id": 1, "pipeline_uuid": "green_taxi_etl", "hostname": "d3de16eb1433", "level": "INFO", "message": "Pipeline green_taxi_etl for run 1 in schedule 1 is alive.", "timestamp": 1707412086.332835, "uuid": "6036561eca9942dd933b4bcca6839a9d"}
2024-02-08T17:08:06 {"block_run_id": 2, "block_uuid": "transform_taxi_data", "pipeline_run_id": 1, "pipeline_schedule_id": 1, "pipeline_uuid": "green_taxi_etl", "hostname": "d3de16eb1433", "level": "INFO", "message": "Execute PipelineRun 1, BlockRun 2: pipeline green_taxi_etl block transform_taxi_data", "timestamp": 1707412086.528844, "uuid": "6d5b0e462267433987265f98ef8d7119"}
2024-02-08T17:08:07 {"block_run_id": 2, "block_uuid": "transform_taxi_data", "pipeline_run_id": 1, "pipeline_schedule_id": 1, "pipeline_uuid": "green_taxi_etl", "hostname": "d3de16eb1433", "level": "INFO", "message": "BlockRun 2 (block_uuid: transform_taxi_data) completes.", "timestamp": 1707412087.674615, "uuid": "47b1069b84c447c3b4056136c75a4be3"}
2024-02-08T17:08:16 {"cpu": 1.58642578125, "cpu_total": 4, "cpu_usage": 0.3966064453125, "memory": 8503.0, "memory_total": 9682.0, "memory_usage": 0.878227638917579, "pipeline_run_id": 1, "pipeline_schedule_id": 1, "pipeline_uuid": "green_taxi_etl", "hostname": "d3de16eb1433", "level": "INFO", "message": "Pipeline green_taxi_etl for run 1 in schedule 1 is alive.", "timestamp": 1707412096.591536, "uuid": "2fb428484c004236a9d9e9de7a224ca4"}
2024-02-08T17:08:16 {"block_run_id": 3, "block_uuid": "export_to_bucket", "pipeline_run_id": 1, "pipeline_schedule_id": 1, "pipeline_uuid": "green_taxi_etl", "hostname": "d3de16eb1433", "level": "INFO", "message": "Execute PipelineRun 1, BlockRun 3: pipeline green_taxi_etl block export_to_bucket", "timestamp": 1707412096.861413, "uuid": "4a93001dcb7140e289c843d115660b60"}
2024-02-08T17:08:17 {"block_run_id": 4, "block_uuid": "taxi_data_to_postgres", "pipeline_run_id": 1, "pipeline_schedule_id": 1, "pipeline_uuid": "green_taxi_etl", "hostname": "d3de16eb1433", "level": "INFO", "message": "Execute PipelineRun 1, BlockRun 4: pipeline green_taxi_etl block taxi_data_to_postgres", "timestamp": 1707412097.888523, "uuid": "2e42015bca2942f8971cf406e3d89824"}
2024-02-08T17:08:18 {"block_run_id": 3, "block_uuid": "export_to_bucket", "pipeline_run_id": 1, "pipeline_schedule_id": 1, "pipeline_uuid": "green_taxi_etl", "hostname": "d3de16eb1433", "level": "EXCEPTION", "message": "BlockRun 3 (block_uuid: export_to_bucket) failed.", "timestamp": 1707412098.252566, "uuid": "2bac68bccfc243f9a69933c58b9a52ad", "error": ["Traceback (most recent call last):\n  File \"/usr/local/lib/python3.10/site-packages/mage_ai/data_preparation/executors/block_executor.py\", line 613, in execute\n    result = __execute_with_retry()\n  File \"/usr/local/lib/python3.10/site-packages/mage_ai/shared/retry.py\", line 54, in retry_func\n    raise e\n  File \"/usr/local/lib/python3.10/site-packages/mage_ai/shared/retry.py\", line 38, in retry_func\n    return func(*args, **kwargs)\n  File \"/usr/local/lib/python3.10/site-packages/mage_ai/data_preparation/executors/block_executor.py\", line 588, in __execute_with_retry\n    return self._execute(\n  File \"/usr/local/lib/python3.10/site-packages/mage_ai/data_preparation/executors/block_executor.py\", line 1077, in _execute\n    result = self.block.execute_sync(\n  File \"/usr/local/lib/python3.10/site-packages/mage_ai/data_preparation/models/block/__init__.py\", line 1312, in execute_sync\n    raise err\n  File \"/usr/local/lib/python3.10/site-packages/mage_ai/data_preparation/models/block/__init__.py\", line 1221, in execute_sync\n    output = self.execute_block(\n  File \"/usr/local/lib/python3.10/site-packages/mage_ai/data_preparation/models/block/__init__.py\", line 1527, in execute_block\n    outputs = self._execute_block(\n  File \"/usr/local/lib/python3.10/site-packages/mage_ai/data_preparation/models/block/__init__.py\", line 1655, in _execute_block\n    exec(self.content, results)\n  File \"<string>\", line 17, in <module>\nNameError: name 'data' is not defined\n"], "error_stack": [["  File \"/usr/local/bin/mage\", line 8, in <module>\n    sys.exit(app())\n", "  File \"/usr/local/lib/python3.10/site-packages/typer/main.py\", line 311, in __call__\n    return get_command(self)(*args, **kwargs)\n", "  File \"/usr/local/lib/python3.10/site-packages/click/core.py\", line 1130, in __call__\n    return self.main(*args, **kwargs)\n", "  File \"/usr/local/lib/python3.10/site-packages/typer/core.py\", line 778, in main\n    return _main(\n", "  File \"/usr/local/lib/python3.10/site-packages/typer/core.py\", line 216, in _main\n    rv = self.invoke(ctx)\n", "  File \"/usr/local/lib/python3.10/site-packages/click/core.py\", line 1657, in invoke\n    return _process_result(sub_ctx.command.invoke(sub_ctx))\n", "  File \"/usr/local/lib/python3.10/site-packages/click/core.py\", line 1404, in invoke\n    return ctx.invoke(self.callback, **ctx.params)\n", "  File \"/usr/local/lib/python3.10/site-packages/click/core.py\", line 760, in invoke\n    return __callback(*args, **kwargs)\n", "  File \"/usr/local/lib/python3.10/site-packages/typer/main.py\", line 683, in wrapper\n    return callback(**use_params)  # type: ignore\n", "  File \"/usr/local/lib/python3.10/site-packages/mage_ai/cli/main.py\", line 163, in start\n    start_server(\n", "  File \"/usr/local/lib/python3.10/site-packages/mage_ai/server/server.py\", line 659, in start_server\n    scheduler_manager.start_scheduler()\n", "  File \"/usr/local/lib/python3.10/site-packages/mage_ai/server/scheduler_manager.py\", line 87, in start_scheduler\n    proc.start()\n", "  File \"/usr/local/lib/python3.10/multiprocessing/process.py\", line 121, in start\n    self._popen = self._Popen(self)\n", "  File \"/usr/local/lib/python3.10/multiprocessing/context.py\", line 224, in _Popen\n    return _default_context.get_context().Process._Popen(process_obj)\n", "  File \"/usr/local/lib/python3.10/multiprocessing/context.py\", line 281, in _Popen\n    return Popen(process_obj)\n", "  File \"/usr/local/lib/python3.10/multiprocessing/popen_fork.py\", line 19, in __init__\n    self._launch(process_obj)\n", "  File \"/usr/local/lib/python3.10/multiprocessing/popen_fork.py\", line 71, in _launch\n    code = process_obj._bootstrap(parent_sentinel=child_r)\n", "  File \"/usr/local/lib/python3.10/multiprocessing/process.py\", line 314, in _bootstrap\n    self.run()\n", "  File \"/usr/local/lib/python3.10/multiprocessing/process.py\", line 108, in run\n    self._target(*self._args, **self._kwargs)\n", "  File \"/usr/local/lib/python3.10/site-packages/mage_ai/orchestration/db/process.py\", line 15, in start_session_and_run\n    results = target(*args)\n", "  File \"/usr/local/lib/python3.10/site-packages/mage_ai/server/scheduler_manager.py\", line 50, in run_scheduler\n    LoopTimeTrigger().start()\n", "  File \"/usr/local/lib/python3.10/site-packages/mage_ai/orchestration/triggers/loop_time_trigger.py\", line 14, in start\n    self.run()\n", "  File \"/usr/local/lib/python3.10/site-packages/mage_ai/orchestration/triggers/time_trigger.py\", line 11, in run\n    schedule_all()\n", "  File \"/usr/local/lib/python3.10/site-packages/mage_ai/orchestration/pipeline_scheduler_original.py\", line 1603, in schedule_all\n    PipelineScheduler(r).schedule()\n", "  File \"/usr/local/lib/python3.10/site-packages/mage_ai/orchestration/db/__init__.py\", line 149, in func_with_rollback\n    return func(*args, **kwargs)\n", "  File \"/usr/local/lib/python3.10/site-packages/mage_ai/orchestration/pipeline_scheduler_original.py\", line 319, in schedule\n    self.__schedule_blocks(block_runs)\n", "  File \"/usr/local/lib/python3.10/site-packages/mage_ai/orchestration/pipeline_scheduler_original.py\", line 584, in __schedule_blocks\n    job_manager.add_job(\n", "  File \"/usr/local/lib/python3.10/site-packages/mage_ai/orchestration/job_manager.py\", line 27, in add_job\n    self.queue.enqueue(job_id, target, *args, **kwargs)\n", "  File \"/usr/local/lib/python3.10/site-packages/mage_ai/orchestration/queue/process_queue.py\", line 108, in enqueue\n    self.start_worker_pool()\n", "  File \"/usr/local/lib/python3.10/site-packages/mage_ai/orchestration/queue/process_queue.py\", line 183, in start_worker_pool\n    self.worker_pool_proc.start()\n", "  File \"/usr/local/lib/python3.10/multiprocessing/process.py\", line 121, in start\n    self._popen = self._Popen(self)\n", "  File \"/usr/local/lib/python3.10/multiprocessing/context.py\", line 224, in _Popen\n    return _default_context.get_context().Process._Popen(process_obj)\n", "  File \"/usr/local/lib/python3.10/multiprocessing/context.py\", line 281, in _Popen\n    return Popen(process_obj)\n", "  File \"/usr/local/lib/python3.10/multiprocessing/popen_fork.py\", line 19, in __init__\n    self._launch(process_obj)\n", "  File \"/usr/local/lib/python3.10/multiprocessing/popen_fork.py\", line 71, in _launch\n    code = process_obj._bootstrap(parent_sentinel=child_r)\n", "  File \"/usr/local/lib/python3.10/multiprocessing/process.py\", line 314, in _bootstrap\n    self.run()\n", "  File \"/usr/local/lib/python3.10/multiprocessing/process.py\", line 108, in run\n    self._target(*self._args, **self._kwargs)\n", "  File \"/usr/local/lib/python3.10/site-packages/mage_ai/orchestration/queue/process_queue.py\", line 288, in poll_job_and_execute\n    worker.start()\n", "  File \"/usr/local/lib/python3.10/multiprocessing/process.py\", line 121, in start\n    self._popen = self._Popen(self)\n", "  File \"/usr/local/lib/python3.10/multiprocessing/context.py\", line 224, in _Popen\n    return _default_context.get_context().Process._Popen(process_obj)\n", "  File \"/usr/local/lib/python3.10/multiprocessing/context.py\", line 281, in _Popen\n    return Popen(process_obj)\n", "  File \"/usr/local/lib/python3.10/multiprocessing/popen_fork.py\", line 19, in __init__\n    self._launch(process_obj)\n", "  File \"/usr/local/lib/python3.10/multiprocessing/popen_fork.py\", line 71, in _launch\n    code = process_obj._bootstrap(parent_sentinel=child_r)\n", "  File \"/usr/local/lib/python3.10/multiprocessing/process.py\", line 314, in _bootstrap\n    self.run()\n", "  File \"/usr/local/lib/python3.10/site-packages/newrelic/api/background_task.py\", line 117, in wrapper\n    return wrapped(*args, **kwargs)\n", "  File \"/usr/local/lib/python3.10/site-packages/mage_ai/orchestration/queue/process_queue.py\", line 253, in run\n    start_session_and_run(args[1], *args[2], **args[3])\n", "  File \"/usr/local/lib/python3.10/site-packages/mage_ai/orchestration/db/process.py\", line 15, in start_session_and_run\n    results = target(*args)\n", "  File \"/usr/local/lib/python3.10/site-packages/mage_ai/orchestration/pipeline_scheduler_original.py\", line 1128, in run_block\n    return ExecutorFactory.get_block_executor(\n", "  File \"/usr/local/lib/python3.10/site-packages/mage_ai/data_preparation/executors/block_executor.py\", line 641, in execute\n    on_failure(\n", "  File \"/usr/local/lib/python3.10/site-packages/mage_ai/orchestration/db/__init__.py\", line 149, in func_with_rollback\n    return func(*args, **kwargs)\n", "  File \"/usr/local/lib/python3.10/site-packages/mage_ai/orchestration/pipeline_scheduler_original.py\", line 415, in on_block_failure\n    self.logger.exception(\n", "  File \"/usr/local/lib/python3.10/site-packages/mage_ai/data_preparation/logging/logger.py\", line 30, in exception\n    self.__send_message('exception', message, **kwargs)\n", "  File \"/usr/local/lib/python3.10/site-packages/mage_ai/data_preparation/logging/logger.py\", line 59, in __send_message\n    data['error_stack'] = traceback.format_stack(),\n"]], "error_stacktrace": ["name 'data' is not defined"]}
Traceback (most recent call last):
  File "/usr/local/lib/python3.10/site-packages/mage_ai/data_preparation/executors/block_executor.py", line 613, in execute
    result = __execute_with_retry()
  File "/usr/local/lib/python3.10/site-packages/mage_ai/shared/retry.py", line 54, in retry_func
    raise e
  File "/usr/local/lib/python3.10/site-packages/mage_ai/shared/retry.py", line 38, in retry_func
    return func(*args, **kwargs)
  File "/usr/local/lib/python3.10/site-packages/mage_ai/data_preparation/executors/block_executor.py", line 588, in __execute_with_retry
    return self._execute(
  File "/usr/local/lib/python3.10/site-packages/mage_ai/data_preparation/executors/block_executor.py", line 1077, in _execute
    result = self.block.execute_sync(
  File "/usr/local/lib/python3.10/site-packages/mage_ai/data_preparation/models/block/__init__.py", line 1312, in execute_sync
    raise err
  File "/usr/local/lib/python3.10/site-packages/mage_ai/data_preparation/models/block/__init__.py", line 1221, in execute_sync
    output = self.execute_block(
  File "/usr/local/lib/python3.10/site-packages/mage_ai/data_preparation/models/block/__init__.py", line 1527, in execute_block
    outputs = self._execute_block(
  File "/usr/local/lib/python3.10/site-packages/mage_ai/data_preparation/models/block/__init__.py", line 1655, in _execute_block
    exec(self.content, results)
  File "<string>", line 17, in <module>
NameError: name 'data' is not defined
2024-02-08T17:08:26 {"cpu": 1.62353515625, "cpu_total": 4, "cpu_usage": 0.4058837890625, "memory": 8871.0, "memory_total": 9682.0, "memory_usage": 0.9162363148109894, "pipeline_run_id": 1, "pipeline_schedule_id": 1, "pipeline_uuid": "green_taxi_etl", "hostname": "d3de16eb1433", "level": "INFO", "message": "Pipeline green_taxi_etl for run 1 in schedule 1 is alive.", "timestamp": 1707412106.931301, "uuid": "d27511f5356e4ee2a40712d33afcbaf8"}
